<?xml version="1.0" encoding="UTF-8"?>
<robot name="EVA02_description">

  <!-- body========================================= -->
  <link name="base">
    <inertial>
      <origin xyz="0.011858 0.000475 0.060237" rpy="0 0 0" />
      <mass value="2.03" />
      <inertia
        ixx="0.013522598" ixy="-0.000075348" ixz="-0.001446647"
        iyy="0.031044571" iyz="-0.000032615"
        izz="0.035960924" />
    </inertial>
    <visual>
      <origin xyz="0 0 0" rpy="0 0 0" />
      <geometry>
        <mesh filename="package://G308_description/meshes/body.STL" />
      </geometry>
      <material name="">
        <color rgba="0.698039215686274 0.698039215686274 0.698039215686274 1" />
      </material>
    </visual>
    <collision>
      <origin xyz="0 0 0" rpy="0 0 0" />
      <geometry>
        <mesh filename="package://G308_description/meshes/body.STL" />
      </geometry>
    </collision>
  </link>

  <!-- camera======================================== -->
  <link name="camera">
    <inertial>
      <origin xyz="0.013017 0 0" rpy="0 0 0" />
      <mass value="0.10" />
      <inertia
        ixx="1.19066e-4"
        ixy="3.2e-8"
        ixz="-1.18e-7"
        iyy="2.8028e-5"
        iyz="5.6e-8"
        izz="1.35348e-4" />
    </inertial>
    <visual>
      <origin xyz="0 0 0" rpy="0 0 0" />
      <geometry>
        <mesh filename="package://G308_description/meshes/camera.STL" />
      </geometry>
      <material name="">
        <color rgba="0.792156862745098 0.819607843137255 0.933333333333333 1" />
      </material>
    </visual>
    <collision>
      <origin xyz="0 0 0" rpy="0 0 0" />
      <geometry>
        <mesh filename="package://G308_description/meshes/camera.STL" />
      </geometry>
    </collision>
  </link>

  <joint name="camera_joint" type="fixed">
    <origin xyz="0.28698 0.0 0.1895" rpy="0 0 0" />
    <parent link="base" />
    <child link="camera" />
    <axis xyz="0 0 0" />
  </joint>

  <!-- lidar========================================= -->
  <link name="lidar">
    <inertial>
      <origin xyz="-0.000200 0.000006 0.017467" rpy="0 0 0" />
      <mass value="0.265" />
      <inertia
        ixx="0.000123746" ixy="0.000000011" ixz="0.000000020"
        iyy="0.000133349" iyz="0.000000035"
        izz="0.000132274" />
    </inertial>
    <visual>
      <origin xyz="0 0 0" rpy="0 0 0" />
      <geometry>
        <mesh filename="package://G308_description/meshes/lidar.STL" />
      </geometry>
      <material name="">
        <color rgba="0.792156862745098 0.819607843137255 0.929411764705882 1" />
      </material>
    </visual>
    <collision>
      <origin xyz="0 0 0" rpy="0 0 0" />
      <geometry>
        <mesh filename="package://G308_description/meshes/lidar.STL" />
      </geometry>
    </collision>
  </link>

  <joint name="lidar_joint" type="fixed">
    <origin xyz="0.264 0.0 0.0985" rpy="0 0 0" />
    <parent link="base" />
    <child link="lidar" />
    <axis xyz="0 0 0" />
  </joint>

  <!-- front left leg========================================= -->
  <link name="FL_hip">
    <inertial>
      <origin xyz="-0.013264 -0.000827 0.000642" rpy="0 0 0" />
      <mass value="0.606" />
      <inertia
        ixx="0.000428373" ixy="0.000001930" ixz="-0.000005377"
        iyy="0.000778855" iyz="0.000000361"
        izz="0.000676550" />
    </inertial>
    <visual>
      <origin xyz="0 0 0" rpy="0 0 0" />
      <geometry>
        <mesh filename="package://G308_description/meshes/FL_hip.STL" />
      </geometry>
      <material name="">
        <color rgba="0.850980392156863 0.850980392156863 0.850980392156863 1" />
      </material>
    </visual>
    <collision>
      <origin xyz="0 0 0" rpy="0 0 0" />
      <geometry>
        <mesh filename="package://G308_description/meshes/FL_hip.STL" />
      </geometry>
    </collision>
  </link>

  <joint name="FL_hip_joint" type="revolute">
    <origin xyz="0.2181 0.09179 0.06815" rpy="0 0 0" />
    <parent link="base" />
    <child link="FL_hip" />
    <axis xyz="1 0 0" />
    <limit lower="-1.0472" upper="1.0472" effort="17.0" velocity="35.0" />
  </joint>

  <link name="FL_thigh">
    <inertial>
      <origin xyz="-0.001468 -0.034831 -0.021338" rpy="0 0 0" />
      <mass value="1.542" />
      <inertia
        ixx="0.007323179" ixy="0.000090584" ixz="-0.000250133"
        iyy="0.006895677" iyz="0.001140375"
        izz="0.002574539" />
    </inertial>
    <visual>
      <origin xyz="0 0 0" rpy="0 0 0" />
      <geometry>
        <mesh filename="package://G308_description/meshes/FL_thigh.STL" />
      </geometry>
      <material name="">
        <color rgba="0.698039215686274 0.698039215686274 0.698039215686274 1" />
      </material>
    </visual>
    <collision>
      <origin xyz="0 0 0" rpy="0 0 0" />
      <geometry>
        <mesh filename="package://G308_description/meshes/FL_thigh.STL" />
      </geometry>
    </collision>
  </link>

  <joint name="FL_thigh_joint" type="revolute">
    <origin xyz="0 0.1271 0" rpy="0 0 0" />
    <parent link="FL_hip" />
    <child link="FL_thigh" />
    <axis xyz="0 1 0" />
    <limit lower="-1.5708" upper="3.4907" effort="17.0" velocity="35.0" />
  </joint>

  <link name="FL_calf">
    <inertial>
      <origin xyz="0.005417 -0.000207 -0.130693" rpy="0 0 0" />
      <mass value="0.227" />
      <inertia
        ixx="0.001988633" ixy="0.000000287" ixz="0.000050642"
        iyy="0.002045846" iyz="-0.000002846"
        izz="0.000076486" />
    </inertial>
    <visual>
      <origin xyz="0 0 0" rpy="0 0 0" />
      <geometry>
        <mesh filename="package://G308_description/meshes/FL_calf.STL" />
      </geometry>
      <material name="">
        <color rgba="0.752941176470588 1 1 1" />
      </material>
    </visual>
    <collision>
      <origin xyz="0 0 0" rpy="0 0 0" />
      <geometry>
        <mesh filename="package://G308_description/meshes/FL_calf.STL" />
      </geometry>
    </collision>
  </link>

  <joint name="FL_calf_joint" type="revolute">
    <origin xyz="0 0 -0.240" rpy="0 0 0" />
    <parent link="FL_thigh" />
    <child link="FL_calf" />
    <axis xyz="0 1 0" />
    <limit lower="-2.7227" upper="-0.83776" effort="60.0" velocity="17.0" />
  </joint>

  <link name="FL_foot">
    <inertial>
      <origin xyz="-0.0141710 0.000000008 -0.014459" rpy="0 0 0" />
      <mass value="0.080" />
      <inertia
        ixx="0.000042354" ixy="0.000000000" ixz="0.000016450"
        iyy="0.000053066" iyz="0.000000000"
        izz="0.000043020" />
    </inertial>
    <visual>
      <origin xyz="0 0 0" rpy="0 0 0" />
      <geometry>
        <mesh filename="package://G308_description/meshes/FL_foot.STL" />
      </geometry>
      <material name="">
        <color rgba="0.501960784313725 0.501960784313725 0.501960784313725 1" />
      </material>
    </visual>
    <collision>
      <origin xyz="0 0 0" rpy="0 0 0" />
      <geometry>
        <mesh filename="package://G308_description/meshes/FL_foot.STL" />
      </geometry>
    </collision>
  </link>

  <joint name="FL_foot_joint" type="fixed" dont_collapse="true">
    <origin xyz="0 0 -0.250" rpy="0 0 0" />
    <parent link="FL_calf" />
    <child link="FL_foot" />
    <axis xyz="0 0 0" />
  </joint>

  <!-- front right leg========================================= -->
  <link name="FR_hip">
    <inertial>
      <origin xyz="-0.013264 0.000827 0.000642" rpy="0 0 0" />
      <mass value="0.606" />
      <inertia
        ixx="0.000428373" ixy="-0.000001930" ixz="-0.000005377"
        iyy="0.000778855" iyz="-0.000000361"
        izz="0.000676550" />
    </inertial>
    <visual>
      <origin xyz="0 0 0" rpy="0 0 0" />
      <geometry>
        <mesh filename="package://G308_description/meshes/FL_hip.STL" scale="1 -1 1" />
      </geometry>
      <material name="">
        <color rgba="0.850980392156863 0.850980392156863 0.850980392156863 1" />
      </material>
    </visual>
    <collision>
      <origin xyz="0 0 0" rpy="0 0 0" />
      <geometry>
        <mesh filename="package://G308_description/meshes/FL_hip.STL" scale="1 -1 1" />
      </geometry>
    </collision>
  </link>

  <joint name="FR_hip_joint" type="revolute">
    <origin xyz="0.2181 -0.09179 0.06815" rpy="0 0 0" />
    <parent link="base" />
    <child link="FR_hip" />
    <axis xyz="1 0 0" />
    <limit lower="-1.0472" upper="1.0472" effort="17.0" velocity="35.0" />
  </joint>

  <link name="FR_thigh">
    <inertial>
      <origin xyz="-0.001468 0.034831 -0.021338" rpy="0 0 0" />
      <mass value="1.542" />
      <inertia
        ixx="0.007323179" ixy="-0.000090584" ixz="-0.000250133"
        iyy="0.006895677" iyz="-0.001140375"
        izz="0.002574539" />
    </inertial>
    <visual>
      <origin xyz="0 0 0" rpy="0 0 0" />
      <geometry>
        <mesh filename="package://G308_description/meshes/FL_thigh.STL" scale="1 -1 1" />
      </geometry>
      <material name="">
        <color rgba="0.698039215686274 0.698039215686274 0.698039215686274 1" />
      </material>
    </visual>
    <collision>
      <origin xyz="0 0 0" rpy="0 0 0" />
      <geometry>
        <mesh filename="package://G308_description/meshes/FL_thigh.STL" scale="1 -1 1" />
      </geometry>
    </collision>
  </link>

  <joint name="FR_thigh_joint" type="revolute">
    <origin xyz="0 -0.1271 0" rpy="0 0 0" />
    <parent link="FR_hip" />
    <child link="FR_thigh" />
    <axis xyz="0 1 0" />
    <limit lower="-1.5708" upper="3.4907" effort="17.0" velocity="35.0" />
  </joint>

  <link name="FR_calf">
    <inertial>
      <origin xyz="0.005417 0.000207 -0.130693" rpy="0 0 0" />
      <mass value="0.227" />
      <inertia
        ixx="0.001988633" ixy="-0.000000287" ixz="0.000050642"
        iyy="0.002045846" iyz="0.000002846"
        izz="0.000076486" />
    </inertial>
    <visual>
      <origin xyz="0 0 0" rpy="0 0 0" />
      <geometry>
        <mesh filename="package://G308_description/meshes/FL_calf.STL" scale="1 -1 1" />
      </geometry>
      <material name="">
        <color rgba="0.752941176470588 1 1 1" />
      </material>
    </visual>
    <collision>
      <origin xyz="0 0 0" rpy="0 0 0" />
      <geometry>
        <mesh filename="package://G308_description/meshes/FL_calf.STL" scale="1 -1 1" />
      </geometry>
    </collision>
  </link>

  <joint name="FR_calf_joint" type="revolute">
    <origin xyz="0 0 -0.240" rpy="0 0 0" />
    <parent link="FR_thigh" />
    <child link="FR_calf" />
    <axis xyz="0 1 0" />
    <limit lower="-2.7227" upper="-0.83776" effort="60.0" velocity="17.0" />
  </joint>

  <link name="FR_foot">
    <inertial>
      <origin xyz="-0.014171 -0.000000008 -0.014459" rpy="0 0 0" />
      <mass value="0.080" />
      <inertia
        ixx="0.000042354" ixy="0.0" ixz="0.000016450"
        iyy="0.000053066" iyz="0.0"
        izz="0.000043020" />
    </inertial>
    <visual>
      <origin xyz="0 0 0" rpy="0 0 0" />
      <geometry>
        <mesh filename="package://G308_description/meshes/FL_foot.STL" scale="1 -1 1" />
      </geometry>
      <material name="">
        <color rgba="0.501960784313725 0.501960784313725 0.501960784313725 1" />
      </material>
    </visual>
    <collision>
      <origin xyz="0 0 0" rpy="0 0 0" />
      <geometry>
        <mesh filename="package://G308_description/meshes/FL_foot.STL" scale="1 -1 1" />
      </geometry>
    </collision>
  </link>

  <joint name="FR_foot_joint" type="fixed" dont_collapse="true">
    <origin xyz="0 0 -0.250" rpy="0 0 0" />
    <parent link="FR_calf" />
    <child link="FR_foot" />
    <axis xyz="0 0 0" />
  </joint>

  <!-- rear left leg========================================= -->
  <link name="RL_hip">
    <inertial>
      <origin xyz="0.011265 -0.004382 -0.000042" rpy="0 0 0" />
      <mass value="0.815" />
      <inertia
        ixx="0.000503754" ixy="-0.000037811" ixz="0.000001175"
        iyy="0.001002948" iyz="0.000000150"
        izz="0.000864619" />
    </inertial>
    <visual>
      <origin xyz="0 0 0" rpy="0 0 0" />
      <geometry>
        <mesh filename="package://G308_description/meshes/RL_hip.STL" />
      </geometry>
      <material name="">
        <color rgba="0.850980392156863 0.850980392156863 0.850980392156863 1" />
      </material>
    </visual>
    <collision>
      <origin xyz="0 0 0" rpy="0 0 0" />
      <geometry>
        <mesh filename="package://G308_description/meshes/RL_hip.STL" />
      </geometry>
    </collision>
  </link>

  <joint name="RL_hip_joint" type="revolute">
    <origin xyz="-0.2206 0.09179 0.06815" rpy="0 0 0" />
    <parent link="base" />
    <child link="RL_hip" />
    <axis xyz="1 0 0" />
    <limit lower="-1.0472" upper="1.0472" effort="17.0" velocity="35.0" />
  </joint>

  <link name="RL_thigh">
    <inertial>
      <origin xyz="-0.001573 -0.032493 -0.021284" rpy="0 0 0" />
      <mass value="1.536" />
      <inertia
        ixx="0.007179038" ixy="0.000080461" ixz="-0.000245207"
        iyy="0.006896888" iyz="0.001057598"
        izz="0.002416899" />
    </inertial>
    <visual>
      <origin xyz="0 0 0" rpy="0 0 0" />
      <geometry>
        <mesh filename="package://G308_description/meshes/RL_thigh.STL" />
      </geometry>
      <material name="">
        <color rgba="0.647058823529412 0.647058823529412 0.647058823529412 1" />
      </material>
    </visual>
    <collision>
      <origin xyz="0 0 0" rpy="0 0 0" />
      <geometry>
        <mesh filename="package://G308_description/meshes/RL_thigh.STL" />
      </geometry>
    </collision>
  </link>

  <joint name="RL_thigh_joint" type="revolute">
    <origin xyz="0 0.1271 0" rpy="0 0 0" />
    <parent link="RL_hip" />
    <child link="RL_thigh" />
    <axis xyz="0 1 0" />
    <limit lower="-1.5708" upper="3.4907" effort="17.0" velocity="35.0" />
  </joint>

  <link name="RL_calf">
    <inertial>
      <origin xyz="0.005417 -0.000207 -0.130693" rpy="0 0 0" />
      <mass value="0.227" />
      <inertia
        ixx="0.001988633" ixy="-0.000000287" ixz="-0.000050642"
        iyy="0.002045846" iyz="-0.000002846"
        izz="0.000076486" />
    </inertial>
    <visual>
      <origin xyz="0 0 0" rpy="0 0 0" />
      <geometry>
        <mesh filename="package://G308_description/meshes/RL_calf.STL" />
      </geometry>
      <material name="">
        <color rgba="0.752941176470588 1 1 1" />
      </material>
    </visual>
    <collision>
      <origin xyz="0 0 0" rpy="0 0 0" />
      <geometry>
        <mesh filename="package://G308_description/meshes/RL_calf.STL" />
      </geometry>
    </collision>
  </link>

  <joint name="RL_calf_joint" type="revolute">
    <origin xyz="0 0 -0.240" rpy="0 0 0" />
    <parent link="RL_thigh" />
    <child link="RL_calf" />
    <axis xyz="0 1 0" />
    <limit lower="-2.7227" upper="-0.83776" effort="60.0" velocity="17.0" />
  </joint>

  <link name="RL_foot">
    <inertial>
      <origin xyz="-0.014171 0.0000000 -0.014459" rpy="0 0 0" />
      <mass value="0.080" />
      <inertia
        ixx="0.000042354" ixy="0.000000000" ixz="0.000016450"
        iyy="0.000053066" iyz="0.000000000"
        izz="0.000043020" />
    </inertial>
    <visual>
      <origin xyz="0 0 0" rpy="0 0 0" />
      <geometry>
        <mesh filename="package://G308_description/meshes/RL_foot.STL" />
      </geometry>
      <material name="">
        <color rgba="1 1 1 1" />
      </material>
    </visual>
    <collision>
      <origin xyz="0 0 0" rpy="0 0 0" />
      <geometry>
        <mesh filename="package://G308_description/meshes/RL_foot.STL" />
      </geometry>
    </collision>
  </link>

  <joint name="RL_foot_joint" type="fixed" dont_collapse="true">
    <origin xyz="0 0 -0.250" rpy="0 0 0" />
    <parent link="RL_calf" />
    <child link="RL_foot" />
    <axis xyz="0 0 0" />
  </joint>

  <!-- rear right leg========================================= -->
  <link name="RR_hip">
    <inertial>
      <origin xyz="0.011265 0.004382 -0.000042" rpy="0 0 0" />
      <mass value="0.815" />
      <inertia
        ixx="0.000503754" ixy="0.000037811" ixz="0.000001175"
        iyy="0.001002948" iyz="-0.000000150"
        izz="0.000864619" />
    </inertial>
    <visual>
      <origin xyz="0 0 0" rpy="0 0 0" />
      <geometry>
        <mesh filename="package://G308_description/meshes/RL_hip.STL" scale="1 -1 1" />
      </geometry>
      <material name="">
        <color rgba="0.850980392156863 0.850980392156863 0.850980392156863 1" />
      </material>
    </visual>
    <collision>
      <origin xyz="0 0 0" rpy="0 0 0" />
      <geometry>
        <mesh filename="package://G308_description/meshes/RL_hip.STL" scale="1 -1 1" />
      </geometry>
    </collision>
  </link>

  <joint name="RR_hip_joint" type="revolute">
    <origin xyz="-0.2206 -0.09179 0.06815" rpy="0 0 0" />
    <parent link="base" />
    <child link="RR_hip" />
    <axis xyz="1 0 0" />
    <limit lower="-1.0472" upper="1.0472" effort="17.0" velocity="35.0" />
  </joint>

  <link name="RR_thigh">
    <inertial>
      <origin xyz="-0.001573 0.032493 -0.021284" rpy="0 0 0" />
      <mass value="1.536" />
      <inertia
        ixx="0.007179038" ixy="-0.000080461" ixz="-0.000245207"
        iyy="0.006896888" iyz="-0.001057598"
        izz="0.002416899" />
    </inertial>
    <visual>
      <origin xyz="0 0 0" rpy="0 0 0" />
      <geometry>
        <mesh filename="package://G308_description/meshes/RL_thigh.STL" scale="1 -1 1" />
      </geometry>
      <material name="">
        <color rgba="0.647058823529412 0.647058823529412 0.647058823529412 1" />
      </material>
    </visual>
    <collision>
      <origin xyz="0 0 0" rpy="0 0 0" />
      <geometry>
        <mesh filename="package://G308_description/meshes/RL_thigh.STL" scale="1 -1 1" />
      </geometry>
    </collision>
  </link>

  <joint name="RR_thigh_joint" type="revolute">
    <origin xyz="0 -0.1271 0" rpy="0 0 0" />
    <parent link="RR_hip" />
    <child link="RR_thigh" />
    <axis xyz="0 1 0" />
    <limit lower="-1.5708" upper="3.4907" effort="17.0" velocity="35.0" />
  </joint>

  <link name="RR_calf">
    <inertial>
      <origin xyz="0.005417 0.000207 -0.130693" rpy="0 0 0" />
      <mass value="0.227" />
      <inertia
        ixx="0.001988633" ixy="0.000000287" ixz="-0.000050642"
        iyy="0.002045846" iyz="0.000002846"
        izz="0.000076486" />
    </inertial>
    <visual>
      <origin xyz="0 0 0" rpy="0 0 0" />
      <geometry>
        <mesh filename="package://G308_description/meshes/RL_calf.STL" scale="1 -1 1" />
      </geometry>
      <material name="">
        <color rgba="0.752941176470588 1 1 1" />
      </material>
    </visual>
    <collision>
      <origin xyz="0 0 0" rpy="0 0 0" />
      <geometry>
        <mesh filename="package://G308_description/meshes/RL_calf.STL" scale="1 -1 1" />
      </geometry>
    </collision>
  </link>

  <joint name="RR_calf_joint" type="revolute">
    <!-- Z 轴无变化，Y 为 0，保持不变 -->
    <origin xyz="0 0 -0.240" rpy="0 0 0" />
    <parent link="RR_thigh" />
    <child link="RR_calf" />
    <axis xyz="0 1 0" />
    <limit lower="-2.7227" upper="-0.83776" effort="60.0" velocity="17.0" />
  </joint>

  <link name="RR_foot">
    <inertial>
      <origin xyz="-0.014171 -0.0000000 -0.014459" rpy="0 0 0" />
      <mass value="0.080" />
      <inertia
        ixx="0.000042354" ixy="0.0" ixz="0.000016450"
        iyy="0.000053066" iyz="0.0"
        izz="0.000043020" />
    </inertial>
    <visual>
      <origin xyz="0 0 0" rpy="0 0 0" />
      <geometry>
        <mesh filename="package://G308_description/meshes/RL_foot.STL" scale="1 -1 1" />
      </geometry>
      <material name="">
        <color rgba="1 1 1 1" />
      </material>
    </visual>
    <collision>
      <origin xyz="0 0 0" rpy="0 0 0" />
      <geometry>
        <mesh filename="package://G308_description/meshes/RL_foot.STL" scale="1 -1 1" />
      </geometry>
    </collision>
  </link>

  <joint name="RR_foot_joint" type="fixed" dont_collapse="true">
    <origin xyz="0 0 -0.250" rpy="0 0 0" />
    <parent link="RR_calf" />
    <child link="RR_foot" />
    <axis xyz="0 0 0" />
  </joint>

</robot>